Workbook

Sheet co 1 coca
A1: Coca cola
A2: Date | B2: Open | C2: High | D2: Low | E2: Close | F2: Adj Close | G2: Volume
A3: 46055 | B3: 75.01 | C3: 75.7 | D3: 74.4 | E3: 75.33 | F3: 75.33 | G3: 19295000
A4: 46048 | B4: 72.86 | C4: 74.9 | D4: 72.27 | E4: 74.81 | F4: 74.81 | G4: 89172900
A5: 46041 | B5: 70 | C5: 73.06 | D5: 69.79 | E5: 72.88 | F5: 72.88 | G5: 76082700
A6: 46034 | B6: 70.9 | C6: 71.71 | D6: 70.04 | E6: 70.44 | F6: 70.44 | G6: 91138000
A7: 46027 | B7: 68.92 | C7: 70.66 | D7: 67.27 | E7: 70.51 | F7: 70.51 | G7: 101305500
A8: 46020 | B8: 70 | C8: 70.42 | D8: 68.98 | E8: 69.12 | F8: 69.12 | G8: 38576900
A9: 46013 | B9: 69.93 | C9: 70.26 | D9: 69.66 | E9: 69.87 | F9: 69.87 | G9: 32526200
A10: 46006 | B10: 70.43 | C10: 71.32 | D10: 70.03 | E10: 70.06 | F10: 70.06 | G10: 102138700
A11: 45999 | B11: 69.84 | C11: 70.69 | D11: 68.79 | E11: 70.52 | F11: 70.52 | G11: 102143800
A12: 45992 | B12: 0.51 Dividend
A13: 45992 | B13: 72.6 | C13: 72.91 | D13: 69.87 | E13: 70 | F13: 69.51 | G13: 82949300
A14: 45985 | B14: 73.16 | C14: 73.23 | D14: 71.57 | E14: 73.12 | F14: 72.61 | G14: 76487900
A15: 45978 | B15: 71.2 | C15: 73.19 | D15: 70.57 | E15: 72.95 | F15: 72.44 | G15: 81901700
A16: 45971 | B16: 70.01 | C16: 71.89 | D16: 69.44 | E16: 71.16 | F16: 70.66 | G16: 72265600
A17: 45964 | B17: 68.8 | C17: 70.87 | D17: 67.66 | E17: 70.55 | F17: 70.06 | G17: 82269300
A18: 45957 | B18: 69.78 | C18: 70.9 | D18: 67.9 | E18: 68.9 | F18: 68.42 | G18: 77814500
A19: 45950 | B19: 68.43 | C19: 71.62 | D19: 67.92 | E19: 69.71 | F19: 69.22 | G19: 99408700
A20: 45943 | B20: 66.23 | C20: 68.5 | D20: 66 | E20: 68.44 | F20: 67.96 | G20: 70378300
A21: 45936 | B21: 66.49 | C21: 67.4 | D21: 65.84 | E21: 67.04 | F21: 66.57 | G21: 70965200
A22: 45929 | B22: 65.67 | C22: 66.99 | D22: 65.35 | E22: 66.65 | F22: 66.19 | G22: 70110900
A23: 45922 | B23: 66.16 | C23: 66.92 | D23: 65.5 | E23: 65.67 | F23: 65.21 | G23: 75347400
A24: 45915 | B24: 0.51 Dividend
A25: 45915 | B25: 66.68 | C25: 67.13 | D25: 66.05 | E25: 66.43 | F25: 65.46 | G25: 100830100
A26: 45908 | B26: 67.86 | C26: 68.17 | D26: 66.94 | E26: 67.01 | F26: 66.04 | G26: 85675300
A27: 45901 | B27: 68.96 | C27: 69.46 | D27: 67.37 | E27: 67.96 | F27: 66.97 | G27: 99065600
A28: 45894 | B28: 70.11 | C28: 70.23 | D28: 68.28 | E28: 68.99 | F28: 67.99 | G28: 73972500
A29: 45887 | B29: 69.98 | C29: 71.71 | D29: 69.05 | E29: 70.13 | F29: 69.11 | G29: 67327900
A30: 45880 | B30: 70.3 | C30: 71.06 | D30: 69.39 | E30: 69.92 | F30: 68.9 | G30: 55430500
A31: 45873 | B31: 68.72 | C31: 70.87 | D31: 68.31 | E31: 70.34 | F31: 69.32 | G31: 58501400
A32: 45866 | B32: 68.74 | C32: 69.42 | D32: 67.74 | E32: 68.86 | F32: 67.86 | G32: 73641300
A33: 45859 | B33: 70.19 | C33: 70.62 | D33: 68.6 | E33: 69.17 | F33: 68.16 | G33: 86267800
A34: 45852 | B34: 69.8 | C34: 70.7 | D34: 68.79 | E34: 69.85 | F34: 68.83 | G34: 75194000
A35: 45845 | B35: 71.37 | C35: 71.37 | D35: 68.97 | E35: 69.87 | F35: 68.85 | G35: 95329400
A36: 45838 | B36: 70.13 | C36: 72.45 | D36: 70.09 | E36: 71.35 | F36: 70.31 | G36: 59649000
... A38: 45824 | B38: 71.2 | C38: 71.62 | D38: 68.78 | E38: 68.84 | F38: 67.84 | G38: 87569900
A39: 45821 | B39: 0.51 Dividend
A40: 45817 | B40: 71.35 | C40: 72.69 | D40: 70.73 | E40: 71.02 | F40: 69.49 | G40: 67538900
A41: 45810 | B41: 72.03 | C41: 72.04 | D41: 70.47 | E41: 71.35 | F41: 69.82 | G41: 66963800
...

Sheet co2 pepsi
A1: Pepsi
A2: Date | B2: Open | C2: High | D2: Low | E2: Close | F2: Adj Close | G2: Volume
A3: 46055 | B3: 154.06 | C3: 156.62 | D3: 153.19 | E3: 155.2 | F3: 155.2 | G3: 14655600
A4: 46048 | B4: 144.8 | C4: 153.89 | D4: 144.14 | E4: 153.63 | F4: 153.63 | G4: 41362200
A5: 46041 | B5: 146.22 | C5: 148.01 | D5: 143.06 | E5: 144.58 | F5: 144.58 | G5: 31699900
A6: 46034 | B6: 139.91 | C6: 147.55 | D6: 138.56 | E6: 146.32 | F6: 146.32 | G6: 45694400
A7: 46027 | B7: 141.66 | C7: 141.81 | D7: 136.01 | E7: 139.91 | F7: 139.91 | G7: 42678100
A8: 46020 | B8: 143.74 | C8: 145.27 | D8: 142.1 | E8: 142.23 | F8: 142.23 | G8: 23478100
A9: 46013 | B9: 147.53 | C9: 148.98 | D9: 142.95 | E9: 143.78 | F9: 143.78 | G9: 23667700
A10: 46006 | B10: 150.94 | C10: 152.35 | D10: 147.9 | E10: 148.16 | F10: 148.16 | G10: 48183700
A11: 45999 | B11: 145.01 | C11: 150.89 | D11: 143.91 | E11: 150.65 | F11: 150.65 | G11: 50886100
A12: 45996 | B12: 1.423 Dividend
A13: 45992 | B13: 148.63 | C13: 150.7 | D13: 144.51 | E13: 145.02 | F13: 143.62 | G13: 32337100
A14: 45985 | B14: 145.83 | C14: 148.82 | D14: 144.76 | E14: 148.74 | F14: 147.3 | G14: 26495300
A15: 45978 | B15: 146.12 | C15: 149.83 | D15: 144.9 | E15: 146.33 | F15: 144.91 | G15: 41055600
A16: 45971 | B16: 142.49 | C16: 146.84 | D16: 141.26 | E16: 145.85 | F16: 144.44 | G16: 32525000
A17: 45964 | B17: 145.86 | C17: 145.91 | D17: 141.3 | E17: 142.95 | F17: 141.57 | G17: 37812500
A18: 45957 | B18: 151.01 | C18: 153.21 | D18: 143.67 | E18: 146.09 | F18: 144.67 | G18: 30205000
A19: 45950 | B19: 154.42 | C19: 155.19 | D19: 151.03 | E19: 151.55 | F19: 150.08 | G19: 26582900
A20: 45943 | B20: 148.65 | C20: 154.38 | D20: 147.34 | E20: 153.71 | F20: 152.22 | G20: 36987200
A21: 45936 | B21: 141.77 | C21: 150.82 | D21: 138.59 | E21: 150.08 | F21: 148.63 | G21: 52369500
A22: 45929 | B22: 140.44 | C22: 143.37 | D22: 139.12 | E22: 141.98 | F22: 140.6 | G22: 35317400
A23: 45922 | B23: 141.08 | C23: 143.42 | D23: 139.85 | E23: 140.44 | F23: 139.08 | G23: 31429600
A24: 45915 | B24: 143.4 | C24: 143.53 | D24: 139.91 | E24: 141.76 | F24: 140.39 | G24: 41128100
A25: 45908 | B25: 145.72 | C25: 145.72 | D25: 140.35 | E25: 143.53 | F25: 142.14 | G25: 34867200
A26: 45905 | B26: 1.423 Dividend
A27: 45901 | B27: 157.44 | C27: 157.8 | D27: 145.28 | E27: 146.39 | F27: 143.57 | G27: 42136300
A28: 45894 | B28: 148.43 | C28: 149.22 | D28: 145.81 | E28: 148.65 | F28: 145.78 | G28: 42951100
A29: 45887 | B29: 150.55 | C29: 154.61 | D29: 148.6 | E29: 149.64 | F29: 146.75 | G29: 41893000
A30: 45880 | B30: 145.32 | C30: 151.1 | D30: 143.75 | E30: 150.4 | F30: 147.5 | G30: 35643800
A31: 45873 | B31: 139.29 | C31: 145.37 | D31: 138.75 | E31: 145.21 | F31: 142.41 | G31: 33656900
A32: 45866 | B32: 142.7 | C32: 144.4 | D32: 137.64 | E32: 139.28 | F32: 136.59 | G32: 45980600
A33: 45859 | B33: 143.1 | C33: 147.03 | D33: 140.46 | E33: 143.45 | F33: 140.68 | G33: 40244100
A34: 45852 | B34: 134.75 | C34: 146.35 | D34: 133.75 | E34: 143.24 | F34: 140.48 | G34: 68269200
A35: 45845 | B35: 135.53 | C35: 136.68 | D35: 132.96 | E35: 135.26 | F35: 132.65 | G35: 40087900
A36: 45838 | B36: 131.2 | C36: 137 | D36: 130.59 | E36: 135.38 | F36: 132.77 | G36: 38579200
A37: 45831 | B37: 129.29 | C37: 131.34 | D37: 127.6 | E37: 131.04 | F37: 128.51 | G37: 71064400
A38: 45824 | B38: 131.31 | C38: 132.09 | D38: 128.59 | E38: 129.07 | F38: 126.58 | G38: 53205700
A39: 45817 | B39: 129.83 | C39: 133.06 | D39: 129.18 | E39: 130.85 | F39: 128.33 | G39: 50500300
A40: 45814 | B40: 1.423 Dividend
...

Sheet 2 combine and clean
A1: Date | B1: Date | E1: Adj Close Adjusted close price adjusted for splits and dividend and/or capital gain distributions. | H1: Daily returns based on adj prices to the left
C2: Adj Close | D2: Adj Close | F2: KO | G2: PEP | H2: PEP
A3: 46055 | B3: 46055 | C3: 75.33 | D3: 155.2 | F3: =(C3-C4)/C4 -> 0.0069509424 | G3: =(D3-D4)/D4 -> 0.010219358
A4: 46048 | B4: 46048 | C4: 74.81 | D4: 153.63 | F4: =(C4-C5)/C5 -> 0.026481888 | G4: =(D4-D5)/D5 -> 0.062595103 | H4: =D3/D4-1 -> 0.010219358
A5: 46041 | B5: 46041 | C5: 72.88 | D5: 144.58 | F5: =(C5-C6)/C6 -> 0.034639409 | G5: =(D5-D6)/D6 -> -0.011891744 | H5: =D4/D5-1 -> 0.062595103
A6: 46034 | B6: 46034 | C6: 70.44 | D6: 146.32 | F6: =(C6-C7)/C7 -> -0.00099276698 | G6: =(D6-D7)/D7 -> 0.045815167 | H6: =D5/D6-1 -> -0.011891744
A7: 46027 | B7: 46027 | C7: 70.51 | D7: 139.91 | F7: =(C7-C8)/C8 -> 0.020109954 | G7: =(D7-D8)/D8 -> -0.016311608 | H7: =D6/D7-1 -> 0.045815167
A8: 46020 | B8: 46020 | C8: 69.12 | D8: 142.23 | F8: =(C8-C9)/C9 -> -0.010734221 | G8: =(D8-D9)/D9 -> -0.010780359 | H8: =D7/D8-1 -> -0.016311608
A9: 46013 | B9: 46013 | C9: 69.87 | D9: 143.78 | F9: =(C9-C10)/C10 -> -0.0027119612 | G9: =(D9-D10)/D10 -> -0.029562635 | H9: =D8/D9-1 -> -0.010780359
A10: 46006 | B10: 46006 | C10: 70.06 | D10: 148.16 | F10: =(C10-C11)/C11 -> -0.0065229722 | G10: =(D10-D11)/D11 -> -0.016528377 | H10: =D9/D10-1 -> -0.029562635
A11: 45999 | B11: 45999 | C11: 70.52 | D11: 150.65 | H11: =D10/D11-1 -> -0.016528377
A12: 45992 | B12: 45996
A13: 45992 | B13: 45992 | C13: 69.51 | D13: 143.62 | F13: =(C13-C14)/C14 -> -0.042693844 | G13: =(D13-D14)/D14 -> -0.024983028
A14: 45985 | B14: 45985 | C14: 72.61 | D14: 147.3 | F14: =(C14-C15)/C15 -> 0.0023467697 | G14: =(D14-D15)/D15 -> 0.016492996 | H14: =D13/D14-1 -> -0.024983028
A15: 45978 | B15: 45978 | C15: 72.44 | D15: 144.91 | F15: =(C15-C16)/C16 -> 0.025191056 | G15: =(D15-D16)/D16 -> 0.0032539463 | H15: =D14/D15-1 -> 0.016492996
A16: 45971 | B16: 45971 | C16: 70.66 | D16: 144.44 | F16: =(C16-C17)/C17 -> 0.0085640879 | G16: =(D16-D17)/D17 -> 0.020272657 | H16: =D15/D16-1 -> 0.0032539463
A17: 45964 | B17: 45964 | C17: 70.06 | D17: 141.57 | F17: =(C17-C18)/C18 -> 0.0239696 | G17: =(D17-D18)/D18 -> -0.021428078 | H17: =D16/D17-1 -> 0.020272657
A18: 45957 | B18: 45957 | C18: 68.42 | D18: 144.67 | F18: =(C18-C19)/C19 -> -0.011557353 | G18: =(D18-D19)/D19 -> -0.036047441 | H18: =D17/D18-1 -> -0.021428078
A19: 45950 | B19: 45950 | C19: 69.22 | D19: 150.08 | F19: =(C19-C20)/C20 -> 0.018540318 | G19: =(D19-D20)/D20 -> -0.014058599 | H19: =D18/D19-1 -> -0.036047441
A20: 45943 | B20: 45943 | C20: 67.96 | D20: 152.22 | F20: =(C20-C21)/C21 -> 0.020880276 | G20: =(D20-D21)/D21 -> 0.024153939 | H20: =D19/D20-1 -> -0.014058599
A21: 45936 | B21: 45936 | C21: 66.57 | D21: 148.63 | F21: =(C21-C22)/C22 -> 0.0057410485 | G21: =(D21-D22)/D22 -> 0.057112376 | H21: =D20/D21-1 -> 0.024153939
A22: 45929 | B22: 45929 | C22: 66.19 | D22: 140.6 | F22: =(C22-C23)/C23 -> 0.01502837 | G22: =(D22-D23)/D23 -> 0.010928962 | H22: =D21/D22-1 -> 0.057112376
A23: 45922 | B23: 45922 | C23: 65.21 | D23: 139.08 | G23: =(D23-D24)/D24 -> -0.0093311489 | H23: =D22/D23-1 -> 0.010928962
A24: 45915 | B24: 45915 | D24: 140.39 | G24: =(D24-D25)/D25 -> -0.012311805 | H24: =D23/D24-1 -> -0.0093311489
A25: 45915 | B25: 45908 | C25: 65.46 | D25: 142.14 | F25: =(C25-C26)/C26 -> -0.008782556 | H25: =D24/D25-1 -> -0.012311805
A26: 45908 | B26: 45905 | C26: 66.04 | F26: =(C26-C27)/C27 -> -0.013886815
A27: 45901 | B27: 45901 | C27: 66.97 | D27: 143.57 | F27: =(C27-C28)/C28 -> -0.015002206 | G27: =(D27-D28)/D28 -> -0.01515983
A28: 45894 | B28: 45894 | C28: 67.99 | D28: 145.78 | F28: =(C28-C29)/C29 -> -0.016206048 | G28: =(D28-D29)/D29 -> -0.0066098807 | H28: =D27/D28-1 -> -0.01515983
A29: 45887 | B29: 45887 | C29: 69.11 | D29: 146.75 | F29: =(C29-C30)/C30 -> 0.0030478955 | G29: =(D29-D30)/D30 -> -0.0050847458 | H29: =D28/D29-1 -> -0.0066098807
A30: 45880 | B30: 45880 | C30: 68.9 | D30: 147.5 | F30: =(C30-C31)/C31 -> -0.0060588575 | G30: =(D30-D31)/D31 -> 0.035741872 | H30: =D29/D30-1 -> -0.0050847458
A31: 45873 | B31: 45873 | C31: 69.32 | D31: 142.41 | F31: =(C31-C32)/C32 -> 0.021514884 | G31: =(D31-D32)/D32 -> 0.042609269 | H31: =D30/D31-1 -> 0.035741872
A32: 45866 | B32: 45866 | C32: 67.86 | D32: 136.59 | F32: =(C32-C33)/C33 -> -0.0044014085 | G32: =(D32-D33)/D33 -> -0.029073074 | H32: =D31/D32-1 -> 0.042609269
A33: 45859 | B33: 45859 | C33: 68.16 | D33: 140.68 | F33: =(C33-C34)/C34 -> -0.0097341276 | G33: =(D33-D34)/D34 -> 0.0014236902 | H33: =D32/D33-1 -> -0.029073074
A34: 45852 | B34: 45852 | C34: 68.83 | D34: 140.48 | F34: =(C34-C35)/C35 -> -0.00029048656 | G34: =(D34-D35)/D35 -> 0.059027516 | H34: =D33/D34-1 -> 0.0014236902
A35: 45845 | B35: 45845 | C35: 68.85 | D35: 132.65 | F35: =(C35-C36)/C36 -> -0.020765183 | G35: =(D35-D36)/D36 -> -0.00090381863 | H35: =D34/D35-1 -> 0.059027516
A36: 45838 | B36: 45838 | C36: 70.31 | D36: 132.77 | F36: =(C36-C37)/C37 -> 0.014427932 | G36: =(D36-D37)/D37 -> 0.033149171 | H36: =D35/D36-1 -> -0.00090381863
A37: 45831 | B37: 45831 | C37: 69.31 | D37: 128.51 | F37: =(C37-C38)/C38 -> 0.021668632 | G37: =(D37-D38)/D38 -> 0.015247274 | H37: =D36/D37-1 -> 0.033149171
A38: 45824 | B38: 45824 | C38: 67.84 | D38: 126.58 | G38: =(D38-D39)/D39 -> -0.013636718 | H38: =D37/D38-1 -> 0.015247274
A39: 45821 | B39: 45817 | D39: 128.33 | H39: =D38/D39-1 -> -0.013636718
A40: 45817 | B40: 45814 | C40: 69.49 | F40: =(C40-C41)/C41 -> -0.0047264394
...

Sheet 2. returns
E1: WEEKLY RETURN FOR KO | F1: WEEKLY RETURN FOR PEP
A2: 46055 | B2: 46055 | C2: Adj Close | D2: Adj Close
A3: 46048 | B3: 46048 | C3: 75.33 | D3: 155.2 | E3: =C3/C4-1 -> 0.0069509424 | F3: =D3/D4-1 -> 0.010219358
A4: 46041 | B4: 46041 | C4: 74.81 | D4: 153.63 | E4: =C4/C5-1 -> 0.026481888 | F4: =D4/D5-1 -> 0.062595103
A5: 46034 | B5: 46034 | C5: 72.88 | D5: 144.58 | E5: =C5/C6-1 -> 0.034639409 | F5: =D5/D6-1 -> -0.011891744
A6: 46027 | B6: 46027 | C6: 70.44 | D6: 146.32 | E6: =C6/C7-1 -> -0.00099276698 | F6: =D6/D7-1 -> 0.045815167
A7: 46020 | B7: 46020 | C7: 70.51 | D7: 139.91 | E7: =C7/C8-1 -> 0.020109954 | F7: =D7/D8-1 -> -0.016311608
A8: 46013 | B8: 46013 | C8: 69.12 | D8: 142.23 | E8: =C8/C9-1 -> -0.010734221 | F8: =D8/D9-1 -> -0.010780359
A9: 46006 | B9: 46006 | C9: 69.87 | D9: 143.78 | E9: =C9/C10-1 -> -0.0027119612 | F9: =D9/D10-1 -> -0.029562635
A10: 45999 | B10: 45999 | C10: 70.06 | D10: 148.16 | E10: =C10/C11-1 -> -0.0065229722 | F10: =D10/D11-1 -> -0.016528377
A11: 45992 | B11: 45996 | C11: 70.52 | D11: 150.65
A12: 45992 | B12: 45992
A13: 45985 | B13: 45985 | C13: 69.51 | D13: 143.62 | E13: =C13/C14-1 -> -0.042693844 | F13: =D13/D14-1 -> -0.024983028
A14: 45978 | B14: 45978 | C14: 72.61 | D14: 147.3 | E14: =C14/C15-1 -> 0.0023467697 | F14: =D14/D15-1 -> 0.016492996
A15: 45971 | B15: 45971 | C15: 72.44 | D15: 144.91 | E15: =C15/C16-1 -> 0.025191056 | F15: =D15/D16-1 -> 0.0032539463
A16: 45964 | B16: 45964 | C16: 70.66 | D16: 144.44 | E16: =C16/C17-1 -> 0.0085640879 | F16: =D16/D17-1 -> 0.020272657
A17: 45957 | B17: 45957 | C17: 70.06 | D17: 141.57 | E17: =C17/C18-1 -> 0.0239696 | F17: =D17/D18-1 -> -0.021428078
A18: 45950 | B18: 45950 | C18: 68.42 | D18: 144.67 | E18: =C18/C19-1 -> -0.011557353 | F18: =D18/D19-1 -> -0.036047441
A19: 45943 | B19: 45943 | C19: 69.22 | D19: 150.08 | E19: =C19/C20-1 -> 0.018540318 | F19: =D19/D20-1 -> -0.014058599
A20: 45936 | B20: 45936 | C20: 67.96 | D20: 152.22 | E20: =C20/C21-1 -> 0.020880276 | F20: =D20/D21-1 -> 0.024153939
A21: 45929 | B21: 45929 | C21: 66.57 | D21: 148.63 | E21: =C21/C22-1 -> 0.0057410485 | F21: =D21/D22-1 -> 0.057112376
A22: 45922 | B22: 45922 | C22: 66.19 | D22: 140.6 | E22: =C22/C23-1 -> 0.01502837 | F22: =D22/D23-1 -> 0.010928962
A23: 45915 | B23: 45915 | C23: 65.21 | D23: 139.08 | F23: =D23/D24-1 -> -0.0093311489
A24: 45915 | B24: 45908 | D24: 140.39 | F24: =D24/D25-1 -> -0.012311805
A25: 45908 | B25: 45905 | C25: 65.46 | D25: 142.14 | E25: =C25/C26-1 -> -0.008782556
A26: 45901 | B26: 45901 | C26: 66.04 | E26: =C26/C27-1 -> -0.013886815
A27: 45894 | B27: 45894 | C27: 66.97 | D27: 143.57 | E27: =C27/C28-1 -> -0.015002206 | F27: =D27/D28-1 -> -0.01515983
A28: 45887 | B28: 45887 | C28: 67.99 | D28: 145.78 | E28: =C28/C29-1 -> -0.016206048 | F28: =D28/D29-1 -> -0.0066098807
A29: 45880 | B29: 45880 | C29: 69.11 | D29: 146.75 | E29: =C29/C30-1 -> 0.0030478955 | F29: =D29/D30-1 -> -0.0050847458
A30: 45873 | B30: 45873 | C30: 68.9 | D30: 147.5 | E30: =C30/C31-1 -> -0.0060588575 | F30: =D30/D31-1 -> 0.035741872
A31: 45866 | B31: 45866 | C31: 69.32 | D31: 142.41 | E31: =C31/C32-1 -> 0.021514884 | F31: =D31/D32-1 -> 0.042609269
A32: 45859 | B32: 45859 | C32: 67.86 | D32: 136.59 | E32: =C32/C33-1 -> -0.0044014085 | F32: =D32/D33-1 -> -0.029073074
A33: 45852 | B33: 45852 | C33: 68.16 | D33: 140.68 | E33: =C33/C34-1 -> -0.0097341276 | F33: =D33/D34-1 -> 0.0014236902
A34: 45845 | B34: 45845 | C34: 68.83 | D34: 140.48 | E34: =C34/C35-1 -> -0.00029048656 | F34: =D34/D35-1 -> 0.059027516
A35: 45838 | B35: 45838 | C35: 68.85 | D35: 132.65 | E35: =C35/C36-1 -> -0.020765183 | F35: =D35/D36-1 -> -0.00090381863
A36: 45831 | B36: 45831 | C36: 70.31 | D36: 132.77 | E36: =C36/C37-1 -> 0.014427932 | F36: =D36/D37-1 -> 0.033149171
A37: 45824 | B37: 45824 | C37: 69.31 | D37: 128.51 | E37: =C37/C38-1 -> 0.021668632 | F37: =D37/D38-1 -> 0.015247274
A38: 45821 | B38: 45817 | C38: 67.84 | D38: 126.58 | F38: =D38/D39-1 -> -0.013636718
A39: 45817 | B39: 45814 | D39: 128.33
A40: 45810 | B40: 45810 | C40: 69.49 | E40: =C40/C41-1 -> -0.0047264394
...

Sheet deescr
C1: KO | D1: PEP
A2: 46055 | B2: 46055 | C2: 0.0069509424 | D2: 0.010219358 | G2: KO | H2: PEP
A3: 46048 | B3: 46048 | C3: 0.026481888 | D3: 0.062595103 | F3: Max | G3: 0.0789 | H3: =MAX(D2:D57) -> 0.070496084
A4: 46041 | B4: 46041 | C4: 0.034639409 | D4: -0.011891744 | F4: Min | G4: =MIN(C2:C5) -> -0.00099276698 | H4: =MIN(D2:D57) -> -0.066248106
A5: 46034 | B5: 46034 | C5: -0.00099276698 | D5: 0.045815167 | F5: range: | G5: =G3-G4 -> 0.079892767 | H5: =H3-H4 -> 0.13674419
A6: 46027 | B6: 46027 | C6: 0.020109954 | D6: -0.016311608
A7: 46020 | B7: 46020 | C7: -0.010734221 | D7: -0.010780359
A8: 46013 | B8: 46013 | C8: -0.0027119612 | D8: -0.029562635 | F8: Q3 | G8: =_xlfn.PERCENTILE.INC(C:C,0.75) -> 0.02091383 | H8: =_xlfn.PERCENTILE.INC(C:C,0.25) -> -0.0090204489
A9: 46006 | B9: 46006 | C9: -0.0065229722 | D9: -0.016528377 | F9: Q1 | G9: =_xlfn.PERCENTILE.INC(C:C,0.025) -> -0.029794184 | H9: =_xlfn.PERCENTILE.INC(D:D,0.25) -> -0.015447774
A10: 45999 | B10: 45999 | F10: IQR, Interquartile range= q3-q1 | G10: =G8-G9 -> 0.050708014 | H10: =H8-H9 -> 0.0064273255
A11: 45992 | B11: 45996
A12: 45992 | B12: 45992 | C12: -0.042693844 | D12: -0.024983028
A13: 45985 | B13: 45985 | C13: 0.0023467697 | D13: 0.016492996
A14: 45978 | B14: 45978 | C14: 0.025191056 | D14: 0.0032539463 | F14: Mean | G14: =AVERAGE(C:C) -> 0.0045404386 | H14: =AVERAGEA(D:D) -> 0.0021098001
A15: 45971 | B15: 45971 | C15: 0.0085640879 | D15: 0.020272657 | F15: Mean Absolute Deviation | G15: =AVEDEV(C:C)*57/56 -> 0.015990429 | H15: =AVEDEV(D:D)*57/56 -> 0.022372873
A16: 45964 | B16: 45964 | C16: 0.0239696 | D16: -0.021428078 | F16: Sample Variance | G16: =_xlfn.VAR.S(C:C) -> 0.00041542184 | H16: =_xlfn.VAR.S(D:D) -> 0.00078912012
A17: 45957 | B17: 45957 | C17: -0.011557353 | D17: -0.036047441 | F17: Sample Standard Deviation | G17: =_xlfn.STDEV.S(C:C) -> 0.0203819 | H17: =_xlfn.STDEV.S(D:D) -> 0.028091282
A18: 45950 | B18: 45950 | C18: 0.018540318 | D18: -0.014058599
A19: 45943 | B19: 45943 | C19: 0.020880276 | D19: 0.024153939
A20: 45936 | B20: 45936 | C20: 0.0057410485 | D20: 0.057112376
A21: 45929 | B21: 45929 | C21: 0.01502837 | D21: 0.010928962
A22: 45922 | B22: 45922 | D22: -0.0093311489
A23: 45915 | B23: 45915 | D23: -0.012311805
A24: 45915 | B24: 45908 | C24: -0.008782556
A25: 45908 | B25: 45905 | C25: -0.013886815
A26: 45901 | B26: 45901 | C26: -0.015002206 | D26: -0.01515983
A27: 45894 | B27: 45894 | C27: -0.016206048 | D27: -0.0066098807
A28: 45887 | B28: 45887 | C28: 0.0030478955 | D28: -0.0050847458
A29: 45880 | B29: 45880 | C29: -0.0060588575 | D29: 0.035741872
A30: 45873 | B30: 45873 | C30: 0.021514884 | D30: 0.042609269
A31: 45866 | B31: 45866 | C31: -0.0044014085 | D31: -0.029073074
A32: 45859 | B32: 45859 | C32: -0.0097341276 | D32: 0.0014236902
A33: 45852 | B33: 45852 | C33: -0.00029048656 | D33: 0.059027516
A34: 45845 | B34: 45845 | C34: -0.020765183 | D34: -0.00090381863
A35: 45838 | B35: 45838 | C35: 0.014427932 | D35: 0.033149171
A36: 45831 | B36: 45831 | C36: 0.021668632 | D36: 0.015247274
A37: 45824 | B37: 45824 | D37: -0.013636718
A38: 45821 | B38: 45817
A39: 45817 | B39: 45814 | C39: -0.0047264394
A40: 45810 | B40: 45810 | C40: -0.010347271 | D40: -0.010821832
...

Sheet sheet 6
A1: Date | B1: Adj Close
A2: 46059 | B2: 6932.3
A3: 46055 | B3: 6932.3 | D3: SNP - Delayed Quote • USD
A4: 46048 | B4: 6939.03 | D4: S&P 500 (^GSPC)
A5: 46041 | B5: 6915.61 | D5: 6,932.30 +133.90 (+1.97%)
A6: 46034 | B6: 6940.01 | D6: At close: February 6 at 4:34:12 PM EST
A7: 46027 | B7: 6966.28 | D7: Currency in USD
A8: 46020 | B8: 6858.47
A9: 46013 | B9: 6929.94
A10: 46006 | B10: 6834.5
A11: 45999 | B11: 6827.41
A12: 45992 | B12: 6870.4
A13: 45985 | B13: 6849.09
A14: 45978 | B14: 6602.99
A15: 45971 | B15: 6734.11
A16: 45964 | B16: 6728.8
A17: 45957 | B17: 6840.2
A18: 45950 | B18: 6791.69
A19: 45943 | B19: 6664.01
... A54: 45698 | B54: 6114.63

Sheet var dev 
A1: week | B1: WEEKLY RETURN FOR KO | C1: WEEKLY RETURN FOR PEP | F1: GROWTH | G1: VALUE
E2: Mean | F2: =AVERAGE(B:B) -> 0.0045404386 | G2: =AVERAGE(C:C) -> 0.0021537543
A3: 1 | B3: 0.0069509424 | C3: 0.010219358 | E3: Mean Absolute Deviation | F3: =AVEDEV(B:B)*56/55 -> 0.01599553 | G3: =AVEDEV(C:C)*56/55 -> 0.022380009
A4: 2 | B4: 0.026481888 | C4: 0.062595103 | E4: Sample Variance | F4: =_xlfn.VAR.S(B:B) -> 0.00041542184 | G4: =_xlfn.VAR.S(C2:C53) -> 0.0007489775
A5: 3 | B5: 0.034639409 | C5: -0.011891744 | E5: Sample Standard Deviation | F5: =_xlfn.STDEV.S(B:B) -> 0.0203819 | G5: =_xlfn.STDEV.S(C:C) -> 0.028091282
A6: 4 | B6: -0.00099276698 | C6: 0.045815167
A7: 5 | B7: 0.020109954 | C7: -0.016311608
A8: 6 | B8: -0.010734221 | C8: -0.010780359 | E8: Performance: Growth outperformed Value, delivering a higher average return of 0.45% compared to 0.22%.
A9: 7 | B9: -0.0027119612 | C9: -0.029562635
A10: 8 | B10: -0.0065229722 | C10: -0.016528377 | E10: Risk: Value is riskier than Growth, with higher volatility as shown by its greater standard deviation (2.81% vs. 2.04%) and variability measures.
A11: 9
A12: 10 | E12: Summary: Overall, Growth provides a better risk-return tradeoff by offering higher returns with lower risk compared to Value.
A13: 11 | B13: -0.042693844 | C13: -0.024983028
A14: 12 | B14: 0.0023467697 | C14: 0.016492996
A15: 13 | B15: 0.025191056 | C15: 0.0032539463
A16: 14 | B16: 0.0085640879 | C16: 0.020272657
A17: 15 | B17: 0.0239696 | C17: -0.021428078
A18: 16 | B18: -0.011557353 | C18: -0.036047441
A19: 17 | B19: 0.018540318 | C19: -0.014058599
A20: 18 | B20: 0.020880276 | C20: 0.024153939
A21: 19 | B21: 0.0057410485 | C21: 0.057112376
A22: 20 | B22: 0.01502837 | C22: 0.010928962
A23: 21 | C23: -0.0093311489
A24: 22 | C24: -0.012311805
A25: 23 | B25: -0.008782556
A26: 24 | B26: -0.013886815
A27: 25 | B27: -0.015002206 | C27: -0.01515983
A28: 26 | B28: -0.016206048 | C28: -0.0066098807
A29: 27 | B29: 0.0030478955 | C29: -0.0050847458
A30: 28 | B30: -0.0060588575 | C30: 0.035741872
A31: 29 | B31: 0.021514884 | C31: 0.042609269
A32: 30 | B32: -0.0044014085 | C32: -0.029073074
A33: 31 | B33: -0.0097341276 | C33: 0.0014236902
A34: 32 | B34: -0.00029048656 | C34: 0.059027516
A35: 33 | B35: -0.020765183 | C35: -0.00090381863
A36: 34 | B36: 0.014427932 | C36: 0.033149171
A37: 35 | B37: 0.021668632 | C37: 0.015247274
A38: 36 | C38: -0.013636718
A39: 37
A40: 38 | B40: -0.0047264394
...

Sheet cvar
A1: week | B1: WEEKLY RETURN FOR KO | C1: WEEKLY RETURN FOR PEP | F1: GROWTH | G1: VALUE
E2: Mean | F2: =AVERAGE(B:B) -> 0.0045404386 | G2: =AVERAGE(C:C) -> 0.0021537543
A3: 1 | B3: 0.0069509424 | C3: 0.010219358 | E3: Mean Absolute Deviation | F3: =AVEDEV(B:B)*56/55 -> 0.01599553 | G3: =AVEDEV(C:C)*56/55 -> 0.022380009
A4: 2 | B4: 0.026481888 | C4: 0.062595103 | E4: Sample Variance | F4: =_xlfn.VAR.S(B:B) -> 0.00041542184 | G4: =_xlfn.VAR.S(C2:C53) -> 0.0007489775
A5: 3 | B5: 0.034639409 | C5: -0.011891744 | E5: Sample Standard Deviation | F5: =_xlfn.STDEV.S(B:B) -> 0.0203819 | G5: =_xlfn.STDEV.S(C:C) -> 0.028091282
A6: 4 | B6: -0.00099276698 | C6: 0.045815167 | E6: CV | F6: =F5/F2 -> 4.4889716 | G6: =G5/G2 -> 13.042937
A7: 5 | B7: 0.020109954 | C7: -0.016311608
A8: 6 | B8: -0.010734221 | C8: -0.010780359
A9: 7 | B9: -0.0027119612 | C9: -0.029562635
A10: 8 | B10: -0.0065229722 | C10: -0.016528377
A11: 9
A12: 10
A13: 11 | B13: -0.042693844 | C13: -0.024983028
A14: 12 | B14: 0.0023467697 | C14: 0.016492996
A15: 13 | B15: 0.025191056 | C15: 0.0032539463
A16: 14 | B16: 0.0085640879 | C16: 0.020272657
A17: 15 | B17: 0.0239696 | C17: -0.021428078
A18: 16 | B18: -0.011557353 | C18: -0.036047441
A19: 17 | B19: 0.018540318 | C19: -0.014058599
A20: 18 | B20: 0.020880276 | C20: 0.024153939
A21: 19 | B21: 0.0057410485 | C21: 0.057112376
A22: 20 | B22: 0.01502837 | C22: 0.010928962
A23: 21 | C23: -0.0093311489
A24: 22 | C24: -0.012311805
A25: 23 | B25: -0.008782556
A26: 24 | B26: -0.013886815
A27: 25 | B27: -0.015002206 | C27: -0.01515983
A28: 26 | B28: -0.016206048 | C28: -0.0066098807
A29: 27 | B29: 0.0030478955 | C29: -0.0050847458
A30: 28 | B30: -0.0060588575 | C30: 0.035741872
A31: 29 | B31: 0.021514884 | C31: 0.042609269
A32: 30 | B32: -0.0044014085 | C32: -0.029073074
A33: 31 | B33: -0.0097341276 | C33: 0.0014236902
A34: 32 | B34: -0.00029048656 | C34: 0.059027516
A35: 33 | B35: -0.020765183 | C35: -0.00090381863
A36: 34 | B36: 0.014427932 | C36: 0.033149171
A37: 35 | B37: 0.021668632 | C37: 0.015247274
A38: 36 | C38: -0.013636718
A39: 37
A40: 38 | B40: -0.0047264394
...

Sheet f test
A1: week | B1: GROWTH | C1: VALUE | F1: GROWTH | G1: VALUE
E2: STDEV.S | F2: =_xlfn.STDEV.S(B:B) -> 0.0203819 | G2: =_xlfn.STDEV.S(C:C) -> 0.028091282
A3: 1 | B3: 0.0069509424 | C3: 0.010219358 | E3: N | F3: 48 | G3: 48
A4: 2 | B4: 0.026481888 | C4: 0.062595103 | E4: DOF | F4: =F3-1 -> 47 | G4: =G3-1 -> 47
A5: 3 | B5: 0.034639409 | C5: -0.011891744 | E5: α | F5: 0.05
A6: 4 | B6: -0.00099276698 | C6: 0.045815167 | E6: X | F6: =_xlfn.VAR.S(B:B)/_xlfn.VAR.S(C:C) -> 0.52643676
A7: 5 | B7: 0.020109954 | C7: -0.016311608 | E7: P VALUE | F7: =_xlfn.F.DIST.RT(F6,F4,G4) -> 0.98497638
A8: 6 | B8: -0.010734221 | C8: -0.010780359
A9: 7 | B9: -0.0027119612 | C9: -0.029562635
A10: 8 | B10: -0.0065229722 | C10: -0.016528377 | E10: We do not reject the null hypothesis because the p-value = 0.985 is greater than alpha = 0.05$.
A11: 9 | E11: Therefore, at the 5% significance level, we cannot conclude that the Growth fund is riskier than the Value fund.
A12: 10
A13: 11 | B13: -0.042693844 | C13: -0.024983028
A14: 12 | B14: 0.0023467697 | C14: 0.016492996
A15: 13 | B15: 0.025191056 | C15: 0.0032539463
A16: 14 | B16: 0.0085640879 | C16: 0.020272657
A17: 15 | B17: 0.0239696 | C17: -0.021428078
A18: 16 | B18: -0.011557353 | C18: -0.036047441
A19: 17 | B19: 0.018540318 | C19: -0.014058599
A20: 18 | B20: 0.020880276 | C20: 0.024153939
A21: 19 | B21: 0.0057410485 | C21: 0.057112376
A22: 20 | B22: 0.01502837 | C22: 0.010928962
A23: 21 | C23: -0.0093311489
A24: 22 | C24: -0.012311805
A25: 23 | B25: -0.008782556
A26: 24 | B26: -0.013886815
A27: 25 | B27: -0.015002206 | C27: -0.01515983
A28: 26 | B28: -0.016206048 | C28: -0.0066098807
A29: 27 | B29: 0.0030478955 | C29: -0.0050847458
A30: 28 | B30: -0.0060588575 | C30: 0.035741872
A31: 29 | B31: 0.021514884 | C31: 0.042609269
A32: 30 | B32: -0.0044014085 | C32: -0.029073074
A33: 31 | B33: -0.0097341276 | C33: 0.0014236902
A34: 32 | B34: -0.00029048656 | C34: 0.059027516
A35: 33 | B35: -0.020765183 | C35: -0.00090381863
A36: 34 | B36: 0.014427932 | C36: 0.033149171
A37: 35 | B37: 0.021668632 | C37: 0.015247274
A38: 36 | C38: -0.013636718
A39: 37
A40: 38 | B40: -0.0047264394
...

Sheet chisq
A1: week | B1: GROWTH | C1: VALUE | E1: GROWTH | F1: VALUE
D2: STDEV.S | E2: =_xlfn.STDEV.S(B:B) -> 0.0203819 | F2: =_xlfn.STDEV.S(C:C) -> 0.028091282
A3: 1 | B3: 0.0069509424 | C3: 0.010219358 | D3: STDEV.P | E3: =_xlfn.STDEV.P(B:B) -> 0.020168471 | F3: =_xlfn.STDEV.P(C:C) -> 0.027797124
A4: 2 | B4: 0.026481888 | C4: 0.062595103 | D4: N | E4: 48 | F4: 48
A5: 3 | B5: 0.034639409 | C5: -0.011891744 | D5: DOF | E5: =E4-1 -> 47 | F5: =F4-1 -> 47
A6: 4 | B6: -0.00099276698 | C6: 0.045815167 | D6: σ₀² | E6: =E3^2 -> 0.00040676722 | F6: =F3^2 -> 0.00077268012
A7: 5 | B7: 0.020109954 | C7: -0.016311608 | D7: χ² | E7: =E5*E8/E6 -> 48 | F7: =F5*F8/F6 -> 48
A8: 6 | B8: -0.010734221 | C8: -0.010780359 | D8: s² | E8: =E2^2 -> 0.00041542184 | F8: =F2^2 -> 0.00078912012
A9: 7 | B9: -0.0027119612 | C9: -0.029562635 | D9: α | E9: 0.05 | F9: 0.05
A10: 8 | B10: -0.0065229722 | C10: -0.016528377 | D10: P VALUE | E10: =2*_xlfn.CHISQ.DIST.RT(E7,E5) -> 0.86412198 | F10: =2*_xlfn.CHISQ.DIST.RT(F7,F5) -> 0.86412198
A11: 9
A12: 10 | D12: Fail to reject H0. There is not sufficient evidence at the 5 percent level alpha = 0.05) to conclude that the population standard deviation differs from the hypothesized value.
A13: 11 | B13: -0.042693844 | C13: -0.024983028 | D13: Since the p-value (0.8641) is greater than alpha, we conclude that the sample data is consistent with the null hypothesis.
A14: 12 | B14: 0.0023467697 | C14: 0.016492996
A15: 13 | B15: 0.025191056 | C15: 0.0032539463
A16: 14 | B16: 0.0085640879 | C16: 0.020272657
A17: 15 | B17: 0.0239696 | C17: -0.021428078
A18: 16 | B18: -0.011557353 | C18: -0.036047441
A19: 17 | B19: 0.018540318 | C19: -0.014058599
A20: 18 | B20: 0.020880276 | C20: 0.024153939
A21: 19 | B21: 0.0057410485 | C21: 0.057112376
A22: 20 | B22: 0.01502837 | C22: 0.010928962
A23: 21 | C23: -0.0093311489
A24: 22 | C24: -0.012311805
A25: 23 | B25: -0.008782556
A26: 24 | B26: -0.013886815
A27: 25 | B27: -0.015002206 | C27: -0.01515983
A28: 26 | B28: -0.016206048 | C28: -0.0066098807
A29: 27 | B29: 0.0030478955 | C29: -0.0050847458
A30: 28 | B30: -0.0060588575 | C30: 0.035741872
A31: 29 | B31: 0.021514884 | C31: 0.042609269
A32: 30 | B32: -0.0044014085 | C32: -0.029073074
A33: 31 | B33: -0.0097341276 | C33: 0.0014236902
A34: 32 | B34: -0.00029048656 | C34: 0.059027516
A35: 33 | B35: -0.020765183 | C35: -0.00090381863
A36: 34 | B36: 0.014427932 | C36: 0.033149171
A37: 35 | B37: 0.021668632 | C37: 0.015247274
A38: 36 | C38: -0.013636718
A39: 37
A40: 38 | B40: -0.0047264394
...

Sheet Z OUTLIERS
A1: week | B1: WEEKLY RETURN FOR KO | C1: WEEKLY RETURN FOR PEP | F1: GROWTH | G1: VALUE
E2: Mean | F2: =AVERAGE(B:B) -> 0.0045404386 | G2: =AVERAGE(C:C) -> 0.0021537543
A3: 1 | B3: 0.0069509424 | C3: 0.010219358 | E3: Mean Absolute Deviation | F3: =AVEDEV(B:B)*56/55 -> 0.01599553 | G3: =AVEDEV(C:C)*56/55 -> 0.022380009
A4: 2 | B4: 0.026481888 | C4: 0.062595103 | E4: Sample Variance | F4: =_xlfn.VAR.S(B:B) -> 0.00041542184 | G4: =_xlfn.VAR.S(C2:C53) -> 0.0007489775 | I4: Z-SCORE
A5: 3 | B5: 0.034639409 | C5: -0.011891744 | E5: Sample Standard Deviation | F5: =_xlfn.STDEV.S(B:B) -> 0.0203819 | G5: =_xlfn.STDEV.S(C:C) -> 0.028091282 | I5: z=x-x bar/s
A6: 4 | B6: -0.00099276698 | C6: 0.045815167 | E6: CV | F6: =F5/F2 -> 4.4889716 | G6: =G5/G2 -> 13.042937 | I6: z=min-mean/sample standart
A7: 5 | B7: 0.020109954 | C7: -0.016311608 | E7: MIN | F7: =MIN(B:B) -> -0.042693844 | G7: =MIN(C:C) -> -0.066248106
A8: 6 | B8: -0.010734221 | C8: -0.010780359 | E8: MAX | F8: =MAX(B:B) -> 0.078858249 | G8: =MAX(C:C) -> 0.070496084
A9: 7 | B9: -0.0027119612 | C9: -0.029562635 | E9: Z MIN | F9: =F7-F2/F5 -> -0.26546202 | G9: =G7-G2/G5 -> -0.14291795
A10: 8 | B10: -0.0065229722 | C10: -0.016528377 | E10: Z MAX | F10: =F8-F2/F5 -> -0.14390992 | G10: =G8-G2/G5 -> -0.0061737632
A11: 9
A12: 10
A13: 11 | B13: -0.042693844 | C13: -0.024983028
A14: 12 | B14: 0.0023467697 | C14: 0.016492996
A15: 13 | B15: 0.025191056 | C15: 0.0032539463
A16: 14 | B16: 0.0085640879 | C16: 0.020272657
A17: 15 | B17: 0.0239696 | C17: -0.021428078
A18: 16 | B18: -0.011557353 | C18: -0.036047441
A19: 17 | B19: 0.018540318 | C19: -0.014058599
A20: 18 | B20: 0.020880276 | C20: 0.024153939
A21: 19 | B21: 0.0057410485 | C21: 0.057112376
A22: 20 | B22: 0.01502837 | C22: 0.010928962
A23: 21 | C23: -0.0093311489
A24: 22 | C24: -0.012311805
A25: 23 | B25: -0.008782556
A26: 24 | B26: -0.013886815
A27: 25 | B27: -0.015002206 | C27: -0.01515983
A28: 26 | B28: -0.016206048 | C28: -0.0066098807
A29: 27 | B29: 0.0030478955 | C29: -0.0050847458
A30: 28 | B30: -0.0060588575 | C30: 0.035741872
A31: 29 | B31: 0.021514884 | C31: 0.042609269
A32: 30 | B32: -0.0044014085 | C32: -0.029073074
A33: 31 | B33: -0.0097341276 | C33: 0.0014236902
A34: 32 | B34: -0.00029048656 | C34: 0.059027516
A35: 33 | B35: -0.020765183 | C35: -0.00090381863
A36: 34 | B36: 0.014427932 | C36: 0.033149171
A37: 35 | B37: 0.021668632 | C37: 0.015247274
A38: 36 | C38: -0.013636718
A39: 37
A40: 38 | B40: -0.0047264394
...

Sheet cov
A1: week | B1: WEEKLY RETURN FOR KO | C1: WEEKLY RETURN FOR PEP | D1: dev KO | E1: dev PEP | F1: Product | I1: GROWTH | J1: VALUE
H2: Cov | I2: =_xlfn.COVARIANCE.S(B2:B41,C2:C41) -> 0.00015873029
A3: 1 | B3: 0.0069509424 | C3: 0.010219358 | D3: =B3-AVERAGE(B:B) -> 0.0024105038 | E3: =C3-AVERAGE(C:C) -> 0.0080656039 | F3: =D3*E3 -> 1.9442169e-05 | H3: Correlation | I3: =CORREL(B2:B41,C2:C41) -> 0.3249568
A4: 2 | B4: 0.026481888 | C4: 0.062595103 | D4: =B4-AVERAGE(B:B) -> 0.021941449 | E4: =C4-AVERAGE(C:C) -> 0.060441349 | F4: =D4*E4 -> 0.0013261708
A5: 3 | B5: 0.034639409 | C5: -0.011891744 | D5: =B5-AVERAGE(B:B) -> 0.030098971 | E5: =C5-AVERAGE(C:C) -> -0.014045498 | F5: =D5*E5 -> -0.00042275505 | H5: manual | I5: =SUM(F:F/56-1) -> -1.0000075
A6: 4 | B6: -0.00099276698 | C6: 0.045815167 | D6: =B6-AVERAGE(B:B) -> -0.0055332056 | E6: =C6-AVERAGE(C:C) -> 0.043661413 | F6: =D6*E6 -> -0.00024158757 | H6: stdve | I6: =STDEV(B:B) -> 0.0203819 | J6: =STDEV(C:C) -> 0.028091282
A7: 5 | B7: 0.020109954 | C7: -0.016311608 | D7: =B7-AVERAGE(B:B) -> 0.015569515 | E7: =C7-AVERAGE(C:C) -> -0.018465362 | F7: =D7*E7 -> -0.00028749674
A8: 6 | B8: -0.010734221 | C8: -0.010780359 | D8: =B8-AVERAGE(B:B) -> -0.015274659 | E8: =C8-AVERAGE(C:C) -> -0.012934113 | F8: =D8*E8 -> 0.00019756417
A9: 7 | B9: -0.0027119612 | C9: -0.029562635 | D9: =B9-AVERAGE(B:B) -> -0.0072523998 | E9: =C9-AVERAGE(C:C) -> -0.031716389 | F9: =D9*E9 -> 0.00023001993
A10: 8 | B10: -0.0065229722 | C10: -0.016528377 | D10: =B10-AVERAGE(B:B) -> -0.011063411 | E10: =C10-AVERAGE(C:C) -> -0.018682131 | F10: =D10*E10 -> 0.00020668809
A11: 9 | D11: =B11-AVERAGE(B:B) -> -0.0045404386 | E11: =C11-AVERAGE(C:C) -> -0.0021537543 | F11: =D11*E11 -> 9.7789891e-06
A12: 10 | D12: =B12-AVERAGE(B:B) -> -0.0045404386 | E12: =C12-AVERAGE(C:C) -> -0.0021537543 | F12: =D12*E12 -> 9.7789891e-06
A13: 11 | B13: -0.042693844 | C13: -0.024983028 | D13: =B13-AVERAGE(B:B) -> -0.047234282 | E13: =C13-AVERAGE(C:C) -> -0.027136782 | F13: =D13*E13 -> 0.0012817864
A14: 12 | B14: 0.0023467697 | C14: 0.016492996 | D14: =B14-AVERAGE(B:B) -> -0.0021936689 | E14: =C14-AVERAGE(C:C) -> 0.014339241 | F14: =D14*E14 -> -3.1455547e-05
A15: 13 | B15: 0.025191056 | C15: 0.0032539463 | D15: =B15-AVERAGE(B:B) -> 0.020650617 | E15: =C15-AVERAGE(C:C) -> 0.001100192 | F15: =D15*E15 -> 2.2719644e-05
A16: 14 | B16: 0.0085640879 | C16: 0.020272657 | D16: =B16-AVERAGE(B:B) -> 0.0040236493 | E16: =C16-AVERAGE(C:C) -> 0.018118902 | F16: =D16*E16 -> 7.2904109e-05
A17: 15 | B17: 0.0239696 | C17: -0.021428078 | D17: =B17-AVERAGE(B:B) -> 0.019429161 | E17: =C17-AVERAGE(C:C) -> -0.023581832 | F17: =D17*E17 -> -0.00045817521
A18: 16 | B18: -0.011557353 | C18: -0.036047441 | D18: =B18-AVERAGE(B:B) -> -0.016097792 | E18: =C18-AVERAGE(C:C) -> -0.038201196 | F18: =D18*E18 -> 0.0006149549
A19: 17 | B19: 0.018540318 | C19: -0.014058599 | D19: =B19-AVERAGE(B:B) -> 0.013999879 | E19: =C19-AVERAGE(C:C) -> -0.016212354 | F19: =D19*E19 -> -0.00022697099
A20: 18 | B20: 0.020880276 | C20: 0.024153939 | D20: =B20-AVERAGE(B:B) -> 0.016339838 | E20: =C20-AVERAGE(C:C) -> 0.022000185 | F20: =D20*E20 -> 0.00035947946
A21: 19 | B21: 0.0057410485 | C21: 0.057112376 | D21: =B21-AVERAGE(B:B) -> 0.0012006099 | E21: =C21-AVERAGE(C:C) -> 0.054958621 | F21: =D21*E21 -> 6.5983865e-05
A22: 20 | B22: 0.01502837 | C22: 0.010928962 | D22: =B22-AVERAGE(B:B) -> 0.010487931 | E22: =C22-AVERAGE(C:C) -> 0.0087752075 | F22: =D22*E22 -> 9.2033773e-05
A23: 21 | C23: -0.0093311489 | D23: =B23-AVERAGE(B:B) -> -0.0045404386 | E23: =C23-AVERAGE(C:C) -> -0.011484903 | F23: =D23*E23 -> 5.2146498e-05
A24: 22 | C24: -0.012311805 | D24: =B24-AVERAGE(B:B) -> -0.0045404386 | E24: =C24-AVERAGE(C:C) -> -0.01446556 | F24: =D24*E24 -> 6.5679985e-05
A25: 23 | B25: -0.008782556 | D25: =B25-AVERAGE(B:B) -> -0.013322995 | E25: =C25-AVERAGE(C:C) -> -0.0021537543 | F25: =D25*E25 -> 2.8694457e-05
A26: 24 | B26: -0.013886815 | D26: =B26-AVERAGE(B:B) -> -0.018427254 | E26: =C26-AVERAGE(C:C) -> -0.0021537543 | F26: =D26*E26 -> 3.9687776e-05
A27: 25 | B27: -0.015002206 | C27: -0.01515983 | D27: =B27-AVERAGE(B:B) -> -0.019542645 | E27: =C27-AVERAGE(C:C) -> -0.017313584 | F27: =D27*E27 -> 0.00033835323
A28: 26 | B28: -0.016206048 | C28: -0.0066098807 | D28: =B28-AVERAGE(B:B) -> -0.020746487 | E28: =C28-AVERAGE(C:C) -> -0.008763635 | F28: =D28*E28 -> 0.00018181464
A29: 27 | B29: 0.0030478955 | C29: -0.0050847458 | D29: =B29-AVERAGE(B:B) -> -0.0014925431 | E29: =C29-AVERAGE(C:C) -> -0.0072385 | F29: =D29*E29 -> 1.0803773e-05
A30: 28 | B30: -0.0060588575 | C30: 0.035741872 | D30: =B30-AVERAGE(B:B) -> -0.010599296 | E30: =C30-AVERAGE(C:C) -> 0.033588118 | F30: =D30*E30 -> -0.0003560104
A31: 29 | B31: 0.021514884 | C31: 0.042609269 | D31: =B31-AVERAGE(B:B) -> 0.016974445 | E31: =C31-AVERAGE(C:C) -> 0.040455514 | F31: =D31*E31 -> 0.0006867099
A32: 30 | B32: -0.0044014085 | C32: -0.029073074 | D32: =B32-AVERAGE(B:B) -> -0.008941847 | E32: =C32-AVERAGE(C:C) -> -0.031226828 | F32: =D32*E32 -> 0.00027922552
A33: 31 | B33: -0.0097341276 | C33: 0.0014236902 | D33: =B33-AVERAGE(B:B) -> -0.014274566 | E33: =C33-AVERAGE(C:C) -> -0.00073006407 | F33: =D33*E33 -> 1.0421348e-05
A34: 32 | B34: -0.00029048656 | C34: 0.059027516 | D34: =B34-AVERAGE(B:B) -> -0.0048309252 | E34: =C34-AVERAGE(C:C) -> 0.056873762 | F34: =D34*E34 -> -0.00027475289
A35: 33 | B35: -0.020765183 | C35: -0.00090381863 | D35: =B35-AVERAGE(B:B) -> -0.025305621 | E35: =C35-AVERAGE(C:C) -> -0.0030575729 | F35: =D35*E35 -> 7.7373782e-05
A36: 34 | B36: 0.014427932 | C36: 0.033149171 | D36: =B36-AVERAGE(B:B) -> 0.0098874939 | E36: =C36-AVERAGE(C:C) -> 0.030995417 | F36: =D36*E36 -> 0.000306467
A37: 35 | B37: 0.021668632 | C37: 0.015247274 | D37: =B37-AVERAGE(B:B) -> 0.017128193 | E37: =C37-AVERAGE(C:C) -> 0.01309352 | F37: =D37*E37 -> 0.00022426835
A38: 36 | C38: -0.013636718 | D38: =B38-AVERAGE(B:B) -> -0.0045404386 | E38: =C38-AVERAGE(C:C) -> -0.015790472 | F38: =D38*E38 -> 7.1695669e-05
A39: 37 | D39: =B39-AVERAGE(B:B) -> -0.0045404386 | E39: =C39-AVERAGE(C:C) -> -0.0021537543 | F39: =D39*E39 -> 9.7789891e-06
A40: 38 | B40: -0.0047264394 | D40: =B40-AVERAGE(B:B) -> -0.009266878 | E40: =C40-AVERAGE(C:C) -> -0.0021537543 | F40: =D40*E40 -> 1.9958578e-05
...

Sheet GSPC
A1: Date | B1: Open | C1: High | D1: Low | E1: Close | F1: Adj Close | G1: Volume
A2: 45698 | B2: 6046.4 | C2: 6127.47 | D2: 6003 | E2: 6114.63 | F2: 6114.63 | G2: 22510590000
A3: 45705 | B3: 6121.6 | C3: 6147.43 | D3: 6008.56 | E3: 6013.13 | F3: 6013.13 | G3: 19495560000
A4: 45712 | B4: 6026.69 | C4: 6043.65 | D4: 5837.66 | E4: 5954.5 | F4: 5954.5 | G4: 26733210000
A5: 45719 | B5: 5968.33 | C5: 5986.09 | D5: 5666.29 | E5: 5770.2 | F5: 5770.2 | G5: 27908150000
A6: 45726 | B6: 5705.37 | C6: 5705.37 | D6: 5504.65 | E6: 5638.94 | F6: 5638.94 | G6: 27732600000
A7: 45733 | B7: 5635.6 | C7: 5715.33 | D7: 5597.76 | E7: 5667.56 | F7: 5667.56 | G7: 28404010000
A8: 45740 | B8: 5718.08 | C8: 5786.95 | D8: 5572.42 | E8: 5580.94 | F8: 5580.94 | G8: 22085260000
A9: 45747 | B9: 5527.91 | C9: 5695.31 | D9: 5069.9 | E9: 5074.08 | F9: 5074.08 | G9: 29999550000
A10: 45754 | B10: 4953.79 | C10: 5481.34 | D10: 4835.04 | E10: 5363.36 | F10: 5363.36 | G10: 37869410000
A11: 45761 | B11: 5441.96 | C11: 5459.46 | D11: 5220.79 | E11: 5282.7 | F11: 5282.7 | G11: 18671180000
A12: 45768 | B12: 5232.94 | C12: 5528.11 | D12: 5101.63 | E12: 5525.21 | F12: 5525.21 | G12: 23198970000
A13: 45775 | B13: 5529.22 | C13: 5700.7 | D13: 5433.24 | E13: 5686.67 | F13: 5686.67 | G13: 24244170000
... A54: 46059 | B54: 6816.74 | C54: 6944.89 | D54: 6816.74 | E54: 6932.3 | F54: 6932.3 | G54: 3842633000

Sheet ratio
A1: week | B1: WEEKLY RETURN FOR KO | C1: WEEKLY RETURN FOR PEP | F1: GROWTH | G1: VALUE
E2: Mean | F2: =AVERAGE(B:B) -> 0.0045404386 | G2: =AVERAGE(C:C) -> 0.0021537543
A3: 1 | B3: 0.0069509424 | C3: 0.010219358 | E3: Mean Absolute Deviation | F3: =AVEDEV(B:B)*56/55 -> 0.01599553 | G3: =AVEDEV(C:C)*56/55 -> 0.022380009 | H3: r=mean-t bill/sample std
A4: 2 | B4: 0.026481888 | C4: 0.062595103 | E4: Sample Variance | F4: =_xlfn.VAR.S(B:B) -> 0.00041542184 | G4: =_xlfn.VAR.S(C2:C53) -> 0.0007489775
A5: 3 | B5: 0.034639409 | C5: -0.011891744 | E5: Sample Standard Deviation | F5: =_xlfn.STDEV.S(B:B) -> 0.0203819 | G5: =_xlfn.STDEV.S(C:C) -> 0.028091282
A6: 4 | B6: -0.00099276698 | C6: 0.045815167 | E6: CV | F6: =F5/F2 -> 4.4889716 | G6: =G5/G2 -> 13.042937
A7: 5 | B7: 0.020109954 | C7: -0.016311608 | E7: T bill | F7: 3.96
A8: 6 | B8: -0.010734221 | C8: -0.010780359
A9: 7 | B9: -0.0027119612 | C9: -0.029562635 | E9: sharpe ratio | F9: =F2-F7/F5 -> -194.28549 | G9: =G2-F7/G5 -> -140.96685
A10: 8 | B10: -0.0065229722 | C10: -0.016528377
A11: 9
A12: 10
A13: 11 | B13: -0.042693844 | C13: -0.024983028
A14: 12 | B14: 0.0023467697 | C14: 0.016492996
A15: 13 | B15: 0.025191056 | C15: 0.0032539463
A16: 14 | B16: 0.0085640879 | C16: 0.020272657
A17: 15 | B17: 0.0239696 | C17: -0.021428078
A18: 16 | B18: -0.011557353 | C18: -0.036047441
A19: 17 | B19: 0.018540318 | C19: -0.014058599
A20: 18 | B20: 0.020880276 | C20: 0.024153939
A21: 19 | B21: 0.0057410485 | C21: 0.057112376
A22: 20 | B22: 0.01502837 | C22: 0.010928962
A23: 21 | C23: -0.0093311489
A24: 22 | C24: -0.012311805
A25: 23 | B25: -0.008782556
A26: 24 | B26: -0.013886815
A27: 25 | B27: -0.015002206 | C27: -0.01515983
A28: 26 | B28: -0.016206048 | C28: -0.0066098807
A29: 27 | B29: 0.0030478955 | C29: -0.0050847458
A30: 28 | B30: -0.0060588575 | C30: 0.035741872
A31: 29 | B31: 0.021514884 | C31: 0.042609269
A32: 30 | B32: -0.0044014085 | C32: -0.029073074
A33: 31 | B33: -0.0097341276 | C33: 0.0014236902
A34: 32 | B34: -0.00029048656 | C34: 0.059027516
A35: 33 | B35: -0.020765183 | C35: -0.00090381863
A36: 34 | B36: 0.014427932 | C36: 0.033149171
A37: 35 | B37: 0.021668632 | C37: 0.015247274
A38: 36 | C38: -0.013636718
A39: 37
A40: 38 | B40: -0.0047264394
...

Sheet synopsis
A1: SYNOPSIS
A2: Synopsis of Portfolio Case: Coca-Cola vs. Pepsi Coca-Cola (KO) and Pepsi (PEP) are two of the largest companies in the global beverage industry and are frequently compared in financial analysis. Because both companies operate in similar markets and compete directly, investors often analyze their stock performance to determine which one may offer a more attractive investment opportunity. Evaluating their returns and risk indicators can provide useful insights for portfolio decisions.
A7: An analysis of weekly return data for Coca-Cola and Pepsi highlights differences in their performance. The mean weekly return for Coca-Cola is 0.004540, while the mean weekly return for Pepsi is 0.002154. The mean represents the average return an investor could expect over time. Based on these values, Coca-Cola produced a higher average weekly return compared to Pepsi during the analyzed period. This suggests that Coca-Cola may offer stronger growth potential in terms of returns.
A14: However, mean return alone does not fully capture the level of risk associated with an investment. To understand the variability of returns, it is important to examine the standard deviation, which measures how much the returns fluctuate around the average value. In this analysis, Coca-Cola has a standard deviation of 0.015996, while Pepsi has a higher standard deviation of 0.022380. The higher standard deviation for Pepsi indicates that its returns vary more significantly from the mean, meaning Pepsi’s stock exhibits greater volatility. In contrast, Coca-Cola’s lower standard deviation suggests more stable performance over time.
A20: The relationship between return and risk is a key factor in investment decisions. Investors generally prefer assets that offer higher returns while maintaining lower levels of volatility. In this comparison, Coca-Cola appears to provide both a higher average return and lower variability in returns compared to Pepsi. This combination may make Coca-Cola more appealing to investors who seek a balance between profitability and stability.
A25: In conclusion, the portfolio analysis indicates that Coca-Cola demonstrates stronger performance in terms of both average returns and risk stability relative to Pepsi. While Coca-Cola shows higher returns and lower volatility, investors should still consider other factors such as market conditions, diversification strategies, and long-term investment goals. As with any financial analysis, past performance does not guarantee future results, and investment decisions should always be made with careful consideration of both risk and potential reward.

Sheet DESCR
A1: =sum(A3:A13) -> 6 | B1: Date | C1: COLA daily return minus the 10-year Treasury return | D1: DAILY ADJ. RETURN ON S&P 500 INDEX (^SPX) minus DAILY 10-year U.S. Treasury note RETURN | E1: GSPC
A2: DO NOT CHANGE THIS COLUMN | B2: 46055 | C2: =vlookup(B2,'2. returns'!A:E,5,0)
B3: =B2-7 -> 46048 | C3: =vlookup(B3,'2. returns'!A:E,5,0) -> 0.0069509424
A4: 1 | B4: =B3-7 -> 46041 | C4: =vlookup(B4,'2. returns'!A:E,5,0) -> 0.026481888
A5: 1 | B5: =B4-7 -> 46034 | C5: =vlookup(B5,'2. returns'!A:E,5,0) -> 0.034639409
A6: 1 | B6: =B5-7 -> 46027 | C6: =vlookup(B6,'2. returns'!A:E,5,0) -> -0.00099276698
A7: 1 | B7: =B6-7 -> 46020 | C7: =vlookup(B7,'2. returns'!A:E,5,0) -> 0.020109954
A8: 1 | B8: =B7-7 -> 46013 | C8: =vlookup(B8,'2. returns'!A:E,5,0) -> -0.010734221
A9: 1 | B9: =B8-7 -> 46006 | C9: =vlookup(B9,'2. returns'!A:E,5,0) -> -0.0027119612
B10: =B9-7 -> 45999 | C10: =vlookup(B10,'2. returns'!A:E,5,0) -> -0.0065229722
B11: =B10-7 -> 45992 | C11: =vlookup(B11,'2. returns'!A:E,5,0)
B12: =B11-7 -> 45985 | C12: =vlookup(B12,'2. returns'!A:E,5,0) -> -0.042693844
B13: =B12-7 -> 45978 | C13: =vlookup(B13,'2. returns'!A:E,5,0) -> 0.0023467697
B14: =B13-7 -> 45971 | C14: =vlookup(B14,'2. returns'!A:E,5,0) -> 0.025191056
B15: =B14-7 -> 45964 | C15: =vlookup(B15,'2. returns'!A:E,5,0) -> 0.0085640879
B16: =B15-7 -> 45957 | C16: =vlookup(B16,'2. returns'!A:E,5,0) -> 0.0239696
B17: =B16-7 -> 45950 | C17: =vlookup(B17,'2. returns'!A:E,5,0) -> -0.011557353
B18: =B17-7 -> 45943 | C18: =vlookup(B18,'2. returns'!A:E,5,0) -> 0.018540318
B19: =B18-7 -> 45936 | C19: =vlookup(B19,'2. returns'!A:E,5,0) -> 0.020880276
B20: =B19-7 -> 45929 | C20: =vlookup(B20,'2. returns'!A:E,5,0) -> 0.0057410485
B21: =B20-7 -> 45922 | C21: =vlookup(B21,'2. returns'!A:E,5,0) -> 0.01502837
... B23: =B22-7 -> 45908 | C23: =vlookup(B23,'2. returns'!A:E,5,0) -> -0.008782556
B24: =B23-7 -> 45901
B25: =B24-7 -> 45894
B26: =B25-7 -> 45887
B27: =B26-7 -> 45880
B28: =B27-7 -> 45873
B29: =B28-7 -> 45866
B30: =B29-7 -> 45859
B31: =B30-7 -> 45852
B32: =B31-7 -> 45845
B33: =B32-7 -> 45838
B34: =B33-7 -> 45831
B35: =B34-7 -> 45824
... B54: =B53-7 -> 45691

Sheet regression data
A1: =sum(A3:A13) -> 6 | B1: Date | C1: COLA daily return minus the 10-year Treasury return | D1: GSPC | E1: PEP daily return minus the 10-year Treasury return | F1: GSPC | G1: WEEKLY RETURN FOR KO | H1: WEEKLY RETURN FOR PEP
A2: DO NOT CHANGE THIS COLUMN | B2: 46055 | L2: Date | M2: Open | N2: High | O2: Low | P2: Close | Q2: Adj Close | R2: Volume
B3: =B2-7 -> 46048 | C3: 0,70% | D3: 6939.03 | E3: 1,02% | F3: 6939.03 | G3: 0.0069509424 | H3: 0.010219358 | L3: 46048 | M3: 6923.23 | N3: 7002.28 | O3: 6870.8 | P3: 6939.03 | Q3: 6939.03 | R3: 29382560000
A4: 1 | B4: =B3-7 -> 46041 | C4: 2,65% | D4: 6915.61 | E4: 6,26% | F4: 6915.61 | G4: 0.026481888 | H4: 0.062595103 | L4: 46041 | M4: 6865.24 | N4: 6934.75 | O4: 6789.05 | P4: 6915.61 | Q4: 6915.61 | R4: 21784530000
A5: 1 | B5: =B4-7 -> 46034 | C5: 3,46% | D5: 6940.01 | E5: -1,19% | F5: 6940.01 | G5: 0.034639409 | H5: -0.011891744 | L5: 46034 | M5: 6944.12 | N5: 6986.33 | O5: 6885.74 | P5: 6940.01 | Q5: 6940.01 | R5: 26112200000
A6: 1 | B6: =B5-7 -> 46027 | C6: -0,10% | D6: 6966.28 | E6: 4,58% | F6: 6966.28 | G6: -0.00099276698 | H6: 0.045815167 | L6: 46027 | M6: 6892.19 | N6: 6978.36 | O6: 6891.56 | P6: 6966.28 | Q6: 6966.28 | R6: 26993190000
A7: 1 | B7: =B6-7 -> 46020 | C7: 2,01% | D7: 6858.47 | E7: -1,63% | F7: 6858.47 | G7: 0.020109954 | H7: -0.016311608 | L7: 46020 | M7: 6903.6 | N7: 6920.21 | O7: 6824.31 | P7: 6858.47 | Q7: 6858.47 | R7: 14297630000
A8: 1 | B8: =B7-7 -> 46013 | C8: -1,07% | D8: 6929.94 | E8: -1,08% | F8: 6929.94 | G8: -0.010734221 | H8: -0.010780359 | L8: 46013 | M8: 6865.21 | N8: 6945.77 | O8: 6855.74 | P8: 6929.94 | Q8: 6929.94 | R8: 12670410000
A9: 1 | B9: =B8-7 -> 46006 | C9: -0,27% | D9: 6834.5 | E9: -2,96% | F9: 6834.5 | G9: -0.0027119612 | H9: -0.029562635 | I9: COLA REGRESSION | L9: 46006 | M9: 6860.19 | N9: 6861.59 | O9: 6720.43 | P9: 6834.5 | Q9: 6834.5 | R9: 28736560000
B10: =B9-7 -> 45999 | C10: -0,65% | D10: 6827.41 | E10: -1,65% | F10: 6827.41 | G10: -0.0065229722 | H10: -0.016528377 | L10: 45999 | M10: 6875.2 | N10: 6903.46 | O10: 6801.79 | P10: 6827.41 | Q10: 6827.41 | R10: 24722970000
B11: =B10-7 -> 45992 | C11: -4,27% | D11: 6870.4 | E11: -2,50% | F11: 6870.4 | L11: 45992 | M11: 6812.3 | N11: 6895.78 | O11: 6799.94 | P11: 6870.4 | Q11: 6870.4 | R11: 23685440000
B12: =B11-7 -> 45985 | C12: 0,23% | D12: 6849.09 | E12: 1,65% | F12: 6849.09 | L12: 45985 | M12: 6636.54 | N12: 6850.86 | O12: 6630.7 | P12: 6849.09 | Q12: 6849.09 | R12: 18086610000
B13: =B12-7 -> 45978 | C13: 2,52% | D13: 6602.99 | E13: 0,33% | F13: 6602.99 | G13: -0.042693844 | H13: -0.024983028 | L13: 45978 | M13: 6713.61 | N13: 6770.35 | O13: 6521.92 | P13: 6602.99 | Q13: 6602.99 | R13: 26911230000
B14: =B13-7 -> 45971 | C14: 0,86% | D14: 6734.11 | E14: 2,03% | F14: 6734.11 | G14: 0.0023467697 | H14: 0.016492996 | L14: 45971 | M14: 6785.36 | N14: 6869.91 | O14: 6646.87 | P14: 6734.11 | Q14: 6734.11 | R14: 26159530000
B15: =B14-7 -> 45964 | C15: 2,40% | D15: 6728.8 | E15: -2,14% | F15: 6728.8 | G15: 0.025191056 | H15: 0.0032539463 | L15: 45964 | M15: 6882.32 | N15: 6882.32 | O15: 6631.44 | P15: 6728.8 | Q15: 6728.8 | R15: 29722800000
B16: =B15-7 -> 45957 | C16: -1,16% | D16: 6840.2 | E16: -3,60% | F16: 6840.2 | G16: 0.0085640879 | H16: 0.020272657 | L16: 45957 | M16: 6845.46 | N16: 6920.34 | O16: 6814.26 | P16: 6840.2 | Q16: 6840.2 | R16: 29717690000
B17: =B16-7 -> 45950 | C17: 1,85% | D17: 6791.69 | E17: -1,41% | F17: 6791.69 | G17: 0.0239696 | H17: -0.021428078 | L17: 45950 | M17: 6690.05 | N17: 6807.11 | O17: 6655.69 | P17: 6791.69 | Q17: 6791.69 | R17: 26251170000
B18: =B17-7 -> 45943 | C18: 2,09% | D18: 6664.01 | E18: 2,42% | F18: 6664.01 | G18: -0.011557353 | H18: -0.036047441 | I18: PEPSI REGRESSION | L18: 45943 | M18: 6622.53 | N18: 6724.12 | O18: 6555.07 | P18: 6664.01 | Q18: 6664.01 | R18: 28010240000
B19: =B18-7 -> 45936 | C19: 0,57% | D19: 6552.51 | E19: 5,71% | F19: 6552.51 | G19: 0.018540318 | H19: -0.014058599 | L19: 45936 | M19: 6733.86 | N19: 6764.58 | O19: 6550.78 | P19: 6552.51 | Q19: 6552.51 | R19: 28515370000
B20: =B19-7 -> 45929 | C20: 1,50% | D20: 6715.79 | E20: 1,09% | F20: 6715.79 | G20: 0.020880276 | H20: 0.024153939 | L20: 45929 | M20: 6661.58 | N20: 6750.87 | O20: 6641 | P20: 6715.79 | Q20: 6715.79 | R20: 28583160000
B21: =B20-7 -> 45922 | C21: -0,88% | D21: 6643.7 | E21: -0,93% | F21: 6643.7 | G21: 0.0057410485 | H21: 0.057112376 | L21: 45922 | M21: 6654.28 | N21: 6699.52 | O21: 6569.22 | P21: 6643.7 | Q21: 6643.7 | R21: 27713200000
B22: =B21-7 -> 45915 | C22: -1,39% | D22: 6664.36 | E22: -1,23% | F22: 6664.36 | G22: 0.01502837 | H22: 0.010928962 | L22: 45915 | M22: 6603.49 | N22: 6671.82 | O22: 6551.15 | P22: 6664.36 | Q22: 6664.36 | R22: 30628230000
B23: =B22-7 -> 45908 | C23: -1,50% | D23: 6584.29 | E23: -1,52% | F23: 6584.29 | H23: -0.0093311489 | L23: 45908 | M23: 6498.09 | N23: 6600.21 | O23: 6483.08 | P23: 6584.29 | Q23: 6584.29 | R23: 25330960000
B24: =B23-7 -> 45901 | C24: -1,62% | D24: 6481.5 | E24: -0,66% | F24: 6481.5 | H24: -0.012311805 | L24: 45901 | M24: 6401.51 | N24: 6532.65 | O24: 6360.58 | P24: 6481.5 | Q24: 6481.5 | R24: 18986250000
B25: =B24-7 -> 45894 | C25: 0,30% | D25: 6460.26 | E25: -0,51% | F25: 6460.26 | G25: -0.008782556 | L25: 45894 | M25: 6457.67 | N25: 6508.23 | O25: 6429.21 | P25: 6460.26 | Q25: 6460.26 | R25: 21589030000
B26: =B25-7 -> 45887 | C26: -0,61% | D26: 6466.91 | E26: 3,57% | F26: 6466.91 | G26: -0.013886815 | L26: 45887 | M26: 6445.02 | N26: 6478.89 | O26: 6343.86 | P26: 6466.91 | Q26: 6466.91 | R26: 22070540000
B27: =B26-7 -> 45880 | C27: 2,15% | D27: 6449.8 | E27: 4,26% | F27: 6449.8 | G27: -0.015002206 | H27: -0.01515983 | L27: 45880 | M27: 6389.67 | N27: 6481.34 | O27: 6364.06 | P27: 6449.8 | Q27: 6449.8 | R27: 24020760000
B28: =B27-7 -> 45873 | C28: -0,44% | D28: 6389.45 | E28: -2,91% | F28: 6389.45 | G28: -0.016206048 | H28: -0.0066098807 | L28: 45873 | M28: 6271.71 | N28: 6395.16 | O28: 6271.71 | P28: 6389.45 | Q28: 6389.45 | R28: 25844550000
B29: =B28-7 -> 45866 | C29: -0,97% | D29: 6238.01 | E29: 0,14% | F29: 6238.01 | G29: 0.0030478955 | H29: -0.0050847458 | L29: 45866 | M29: 6397.69 | N29: 6427.02 | O29: 6212.69 | P29: 6238.01 | Q29: 6238.01 | R29: 26921040000
B30: =B29-7 -> 45859 | C30: -0,03% | D30: 6388.64 | E30: 5,90% | F30: 6388.64 | G30: -0.0060588575 | H30: 0.035741872 | L30: 45859 | M30: 6304.74 | N30: 6395.82 | O30: 6281.71 | P30: 6388.64 | Q30: 6388.64 | R30: 26068830000
B31: =B30-7 -> 45852 | C31: -2,08% | D31: 6296.79 | E31: -0,09% | F31: 6296.79 | G31: 0.021514884 | H31: 0.042609269 | L31: 45852 | M31: 6255.15 | N31: 6315.61 | O31: 6201.59 | P31: 6296.79 | Q31: 6296.79 | R31: 25730370000
B32: =B31-7 -> 45845 | C32: 1,44% | D32: 6259.75 | E32: 3,31% | F32: 6259.75 | G32: -0.0044014085 | H32: -0.029073074 | L32: 45845 | M32: 6259.04 | N32: 6290.22 | O32: 6201 | P32: 6259.75 | Q32: 6259.75 | R32: 25812670000
B33: =B32-7 -> 45838 | C33: 2,17% | D33: 6279.35 | E33: 1,52% | F33: 6279.35 | G33: -0.0097341276 | H33: 0.0014236902 | L33: 45838 | M33: 6193.36 | N33: 6284.65 | O33: 6174.97 | P33: 6279.35 | Q33: 6279.35 | R33: 21082030000
B34: =B33-7 -> 45831 | C34: -0,47% | D34: 6173.07 | E34: -1,36% | F34: 6173.07 | G34: -0.00029048656 | H34: 0.059027516 | L34: 45831 | M34: 5969.67 | N34: 6187.68 | O34: 5943.23 | P34: 6173.07 | Q34: 6173.07 | R34: 29409290000
B35: =B34-7 -> 45824 | C35: -1,03% | D35: 5967.84 | E35: -1,08% | F35: 5967.84 | G35: -0.020765183 | H35: -0.00090381863 | L35: 45824 | M35: 6004 | N35: 6050.83 | O35: 5952.56 | P35: 5967.84 | Q35: 5967.84 | R35: 22625380000
B36: =B35-7 -> 45817 | C36: 0,46% | D36: 5976.97 | E36: 1,63% | F36: 5976.97 | G36: 0.014427932 | H36: 0.033149171 | L36: 45817 | M36: 6004.63 | N36: 6059.4 | O36: 5963.21 | P36: 5976.97 | Q36: 5976.97 | R36: 24565200000
B37: =B36-7 -> 45810 | C37: -0,31% | D37: 6000.36 | E37: -2,00% | F37: 6000.36 | G37: 0.021668632 | H37: 0.015247274 | L37: 45810 | M37: 5896.68 | N37: 6016.87 | O37: 5861.43 | P37: 6000.36 | Q37: 6000.36 | R37: 24073530000
B38: =B37-7 -> 45803 | C38: 2,10% | D38: 5911.69 | E38: 1,18% | F38: 5911.69 | H38: -0.013636718 | L38: 45803 | M38: 5854.07 | N38: 5943.13 | O38: 5843.66 | P38: 5911.69 | Q38: 5911.69 | R38: 20979720000
B39: =B38-7 -> 45796 | C39: -1,58% | D39: 5802.82 | E39: -2,47% | F39: 5802.82 | L39: 45796 | M39: 5902.88 | N39: 5968.61 | O39: 5767.41 | P39: 5802.82 | Q39: 5802.82 | R39: 23634980000
B40: =B39-7 -> 45789 | C40: -0,36% | D40: 5958.38 | E40: 0,28% | F40: 5958.38 | G40: -0.0047264394 | L40: 45789 | M40: 5807.2 | N40: 5958.62 | O40: 5786.08 | P40: 5958.38 | Q40: 5958.38 | R40: 26606460000
...

Sheet Sheet17
A1: WEEKLY RETURN FOR KO | B1: WEEKLY RETURN FOR PEP
A2: 0,70% | B2: 1,02%
A3: 2,65% | B3: 6,26%
A4: 3,46% | B4: -1,19%
A5: -0,10% | B5: 4,58%
A6: 2,01% | B6: -1,63%
A7: -1,07% | B7: -1,08%
A8: -0,27% | B8: -2,96%
A9: -0,65% | B9: -1,65%
A10: -4,27% | B10: -2,50%
A11: 0,23% | B11: 1,65%
A12: 2,52% | B12: 0,33%
... A49: 7,89% | B49: -0,82%
